Workbook

Sheet Roadmap
B1: Roadmap проекта: 3 этапа за 6 месяцев
B2: От усиления ДЦО через персонализацию — к полноценному CVM — к промышленному масштабу и оптимизации
B4: ЭТАП 1 · июль–август 2026 | F4: ЭТАП 2 · сентябрь–ноябрь 2026 | J4: ЭТАП 3 · декабрь 2026
B5: Персонализация ДЦО | F5: Полноценный CVM: 100 сегментов | J5: Масштаб + простая оптимизация
B6: ЧТО ДЕЛАЕМ: • Перевод ДЦО-акций на персональные рассылки • Интеграция готового модуля сегментации MCI • Автоматические контрольные группы • Запуск агентов: сегментатор, персонализатор, копирайтер, редактор-гуманизатор • База знаний + бизнес-процесс заведения ДЦО ЧТО ЭТО ДАЁТ: • Рост пенетрации, отдача акций ДЦО выше • +27 млн ₽/мес доп. товарооборота ДЦО • Фундамент для масштабирования CVM | E6: → | F6: ЧТО ДЕЛАЕМ: • Масштаб до 100 сегментов (на базе MCI) • Конвейер массовой генерации контента • Операционный интерфейс заведения акций • Запуск агентов: дизайнер баннеров, оптимизатор • Дашборды эффективности и постэффекты ЧТО ЭТО ДАЁТ: • Полноценный персонализированный CVM-движок • +208 млн ₽/мес доп. товарооборота CVM • Скорость и охват кампаний кратно выше | I6: → | J6: ЧТО ДЕЛАЕМ: • Простой оптимизатор: автоподбор оффера/частоты, антидубли, приоритизация • Формирование 200 акций • Допиливание интерфейса • Передача сервиса заказчику ЧТО ЭТО ДАЁТ: • Промышленный масштаб — 200 акций • Доп ТО CVM до 416 млн ₽/мес • Автономность и готовность к передаче
B8: ИТОГ: совокупный доп. товарооборот за 6 мес ~1,28 млрд ₽ (ДЦО 243 млн + CVM 1 040 млн). 100 сегментов, 200 акций/мес, 7 обученных агентов. Сервис на нашем сервере с передачей заказчику.
B10: КЛЮЧЕВЫЕ ПОКАЗАТЕЛИ | F10: ДОП. ТОВАРООБОРОТ, млн ₽
B11: ROI за период | D11: 2355 | F11: Месяц | G11: ДЦО | H11: CVM | I11: Итого
B12: Чистый эффект за 6 мес | D12: 246149650 | F12: июль.26 | G12: 27000000 | I12: 27000000
B13: Валовая прибыль за 6 мес | D13: =D12*0.3 | F13: авг.26 | G13: 27000000 | I13: 27000000
B14: Итого затраты за 6 мес (работы + инфра + подписки) | D14: 10450350 | F14: сент.26 | G14: 27000000 | H14: 208000000 | I14: 235000000
B15: Доп ТО на 1 ₽ затрат | D15: 123 | F15: окт.26 | G15: 54000000 | H15: 208000000 | I15: 262000000
B16: Доля затрат в доп. товарообороте | D16: 0.81 | F16: ноя.26 | G16: 54000000 | H16: 208000000 | I16: 262000000
B17: Окупаемость (накопл. эффект > 0) | D17: июль.26 | F17: дек.26 | G17: 54000000 | H17: 416000000 | I17: 470000000
F18: ИТОГО | G18: 243000000 | H18: 1040000000 | I18: 1283000000

Sheet Трудоёмкость (детально)
A1: Детальный план работ — помесячно (ставка 4 350 ₽/час, без НДС)
A3: № | B3: Этап | C3: Задача | D3: Блок | E3: Роль | F3: июль.26 | G3: авг.26 | H3: сент.26 | I3: окт.26 | J3: ноя.26 | K3: дек.26 | L3: Часы
A4: ЭТАП 1 — Персонализация ДЦО (июль–август)
A5: 1.1 | B5: Этап 1 | C5: Развёртывание сервиса на нашем сервере: окружение, домены, доступы, безопасность, бэкапы | D5: Технический | E5: Data engineer | F5: 34 | G5: 22 | L5: =SUM(F5:K5)
A6: 1.2 | B6: Этап 1 | C6: Интеграция источников данных ДЦО (клиенты, история покупок, текущие ДЦО-акции) | D6: Технический | E6: Data engineer | F6: 12 | G6: 18 | L6: =SUM(F6:K6)
A7: 1.3 | B7: Этап 1 | C7: Интеграция готового модуля сегментации MCI в проект + интерфейс выбора сегментов | D7: Технический | E7: Data engineer + Backend | F7: 46 | G7: 24 | L7: =SUM(F7:K7)
A8: 1.4 | B8: Этап 1 | C8: Настройка автоматических контрольных групп (на базе MCI) | D8: Технический | E8: CVM-аналитик | F8: 18 | G8: 22 | L8: =SUM(F8:K8)
A9: 1.5 | B9: Этап 1 | C9: Движок персонализации текстов ДЦО (адаптация генератора под сегмент) | D9: Технический | E9: AI-инженер | F9: 61 | G9: 49 | L9: =SUM(F9:K9)
A10: 1.6 | B10: Этап 1 | C10: Методология персонализации ДЦО (карта сегмент → оффер) | D10: Операционный | E10: Руководитель проекта / CVM-методолог | F10: 14 | G10: 26 | L10: =SUM(F10:K10)
A11: 1.7 | B11: Этап 1 | C11: Перевод текущих ДЦО-акций в персональный формат (контент) | D11: Операционный | E11: AI-инженер + маркетолог | F11: 70 | G11: 30 | L11: =SUM(F11:K11)
A12: 1.8 | B12: Этап 1 | C12: Создание базы знаний: шаблоны, скиллы, гайдлайны, tone of voice | D12: Операционный | E12: AI-инженер + маркетолог | F12: 30 | G12: 30 | L12: =SUM(F12:K12)
A13: 1.9 | B13: Этап 1 | C13: Согласование и выстраивание бизнес-процесса планирования и заведения ДЦО | D13: Операционный | E13: Руководитель проекта + аналитик | F13: 27 | G13: 33 | L13: =SUM(F13:K13)
A14: 1.10 | B14: Этап 1 | C14: Пилотный запуск + аналитика постэффектов vs контрольная группа | D14: Операционный | E14: CVM-аналитик | F14: 36 | G14: 24 | L14: =SUM(F14:K14)
A15: 1.11 | B15: Этап 1 | C15: Управление этапом: статусы, демо, приёмка | D15: Операционный | E15: Руководитель проекта / CVM-методолог | F15: 22 | G15: 42 | L15: =SUM(F15:K15)
A16: 1.12 | B16: Этап 1 | C16: Аренда и настройка отдельных серверов под агентов: изолированные среды, оркестрация, мониторинг | D16: Технический | E16: Data engineer | F16: 22 | G16: 18 | L16: =SUM(F16:K16)
A17: 1.13 | B17: Этап 1 | C17: Безопасность: шифрование и дешифровка данных для агентов (доступ к ПДн, маскирование, ключи) | D17: Технический | E17: Data engineer / безопасность | F17: 26 | G17: 14 | L17: =SUM(F17:K17)
A18: ЭТАП 2 — Полноценный CVM: 100 сегментов (сентябрь–ноябрь)
A19: 2.1 | B19: Этап 2 | C19: Интеграция и настройка 100 сегментов MCI в проекте (конфиг, обновление, выгрузки) | D19: Технический | E19: Data engineer | H19: 31 | I19: 27 | J19: 32 | L19: =SUM(F19:K19)
A20: 2.2 | B20: Этап 2 | C20: Конвейер массовой генерации контента (push / купон / баннер / e-mail) | D20: Технический | E20: AI-инженер + маркетолог | H20: 39 | I20: 52 | J20: 39 | L20: =SUM(F20:K20)
A21: 2.3 | B21: Этап 2 | C21: Операционный интерфейс заведения акций (бриф → сегмент → механика → контент → расписание → выгрузка) | D21: Технический | E21: Backend-разработчик | H21: 44 | I21: 33 | J21: 33 | L21: =SUM(F21:K21)
A22: 2.4 | B22: Этап 2 | C22: Интеграция деплинков, SKU и механик в конвейер | D22: Технический | E22: Data engineer | H22: 27 | I22: 21 | J22: 12 | L22: =SUM(F22:K22)
A23: 2.15 | B23: Этап 2 | C23: Разработка агента-конструктора акций: сборка механики, условий, SKU/деплинков, расчёт выгоды и сроков | D23: Технический | E23: AI-инженер | H23: 18 | I23: 31 | J23: 41 | L23: =SUM(F23:K23)
A24: 2.16 | B24: Этап 2 | C24: Разработка агента-оператора заведения акций: автозаполнение полей, расписание, выгрузка, валидация, ввод в систему | D24: Технический | E24: AI-инженер + Backend | H24: 32 | I24: 24 | J24: 24 | L24: =SUM(F24:K24)
A25: 2.5 | B25: Этап 2 | C25: Простой оптимизатор по акциям (подбор оффера под сегмент, правила/скоринг) | D25: Технический | E25: AI-инженер | H25: 30 | I25: 30 | J25: 40 | L25: =SUM(F25:K25)
A26: 2.6 | B26: Этап 2 | C26: Дашборд эффективности и аналитика постэффектов сегментных акций / контрольных групп | D26: Технический | E26: CVM-аналитик | H26: 45 | I26: 27 | J26: 18 | L26: =SUM(F26:K26)
A27: 2.7 | B27: Этап 2 | C27: Формирование контента под 100 сегментов (тексты, проверка ToV, скиллы) | D27: Операционный | E27: AI-инженер + маркетолог | H27: 32 | I27: 52 | J27: 46 | L27: =SUM(F27:K27)
A28: 2.8 | B28: Этап 2 | C28: Операционная часть заведения акций (настройка, расписание, QA) | D28: Операционный | E28: Маркетолог + аналитик | H28: 31 | I28: 36 | J28: 23 | L28: =SUM(F28:K28)
A29: 2.9 | B29: Этап 2 | C29: Выстраивание бизнес-процесса планирования и согласования сетки CVM-акций | D29: Операционный | E29: Руководитель проекта + аналитик | H29: 21 | I29: 32 | J29: 17 | L29: =SUM(F29:K29)
A30: 2.10 | B30: Этап 2 | C30: Методология 100 сегментов (карта сегмент → категория → механика) | D30: Операционный | E30: Руководитель проекта / CVM-методолог | H30: 10 | I30: 20 | J30: 20 | L30: =SUM(F30:K30)
... A34: 2.14 | B34: Этап 2 | C34: Безопасность: дешифровка и подготовка данных для аналитики (постэффекты, контрольные группы, дашборды) | D34: Технический | E34: CVM-аналитик + Data engineer | H34: 8 | I34: 10 | J34: 12 | L34: =SUM(F34:K34)
A35: ЭТАП 3 — Масштаб + простая оптимизация (декабрь)
A36: 3.1 | B36: Этап 3 | C36: Допиливание и стабилизация интерфейса заведения акций | D36: Технический | E36: Backend-разработчик | K36: 60 | L36: =SUM(F36:K36)
A37: 3.2 | B37: Этап 3 | C37: Формирование 200 акций (массовое заведение через конвейер) | D37: Операционный | E37: AI-инженер + маркетолог | K37: 90 | L37: =SUM(F37:K37)
A38: 3.3 | B38: Этап 3 | C38: Простая оптимизация: автоподбор оффера и частоты, антидубли, приоритизация | D38: Технический | E38: AI-инженер | K38: 70 | L38: =SUM(F38:K38)
A39: 3.4 | B39: Этап 3 | C39: Аналитика постэффектов по 200 акциям, финальный отчёт | D39: Операционный | E39: CVM-аналитик | K39: 45 | L39: =SUM(F39:K39)
A40: 3.5 | B40: Этап 3 | C40: Подготовка к передаче сервиса заказчику (документация, runbook, доступы) | D40: Операционный | E40: Data engineer | K40: 45 | L40: =SUM(F40:K40)
A41: 3.6 | B41: Этап 3 | C41: Управление этапом, приёмка, передача | D41: Операционный | E41: Руководитель проекта / CVM-методолог | K41: 35 | L41: =SUM(F41:K41)
C42: ИТОГО ПО МЕСЯЦАМ, часы | F42: =SUM(F4:F41) | G42: =SUM(G4:G41) | H42: =SUM(H4:H41) | I42: =SUM(I4:I41) | J42: =SUM(J4:J41) | K42: =SUM(K4:K41) | L42: =SUM(L4:L41)
C43: ИТОГО ПО МЕСЯЦАМ, ₽ | F43: =F42*4350 | G43: =G42*4350 | H43: =H42*4350 | I43: =I42*4350 | J43: =J42*4350 | K43: =K42*4350 | L43: =L42*4350
A45: ДОПОЛНИТЕЛЬНЫЕ РАСХОДЫ (вне трудозатрат по часам)
...

Sheet Агенты
A1: Агенты, которых обучаем и запускаем в рамках процесса
A2: Каждый агент исполняется в изолированной арендованной среде (см. задачу 1.12 и доп. расходы).
A4: Агент | B4: Функция | C4: Обучаем / настраиваем (этап, задачи) | D4: Запуск | E4: Модель / основа
A5: 1. Агент-сегментатор | B5: Выбор аудитории и сегментов под акцию, контрольные группы | C5: Этап 1 (1.3, 1.4) → масштаб Этап 2 (2.1) | D5: июль | E5: Модуль MCI + интеграция
A6: 2. Агент-персонализатор | B6: Подбор оффера под сегмент (сегмент → оффер) | C6: Этап 1 (1.5) | D6: июль-авг | E6: Claude Max + правила CVM
A7: 3. Агент-копирайтер | B7: Генерация текстов: push / купон / баннер / e-mail | C7: Этап 1 (1.7) → масштаб Этап 2 (2.2, 2.7) | D7: авг-сент | E7: Claude Max + скиллы (hook-generator, frameworks)
A8: 4. Агент-редактор / гуманизатор | B8: Проверка качества, tone of voice, антишаблон | C8: Этап 1 (1.8) | D8: авг | E8: Claude Max + скиллы (humanizer, beautiful-prose, voice-builder)
A9: 5. Агент-дизайнер баннеров | B9: Генерация изображений и баннеров | C9: Этап 2 (2.2, 2.13) | D9: сент-окт | E9: Nano Banana / Google AI Ultra
A10: 6. Агент-оптимизатор | B10: Подбор оффера/частоты, антидубли, приоритизация акций | C10: Этап 2 (2.5) → Этап 3 (3.3) | D10: ноя-дек | E10: Claude Max + скоринг/правила
A11: 7. Агент-аналитик постэффектов | B11: Расчёт эффекта vs контрольные группы, отчёты | C11: Этап 1 (1.10) → Этап 2 (2.6) → Этап 3 (3.4) | D11: июль-дек | E11: Внутренние модели + дашборд
A12: 8. Агент-конструктор акций | B12: Собирает акцию: механика, условия, SKU/деплинки, расчёт выгоды, сроки | C12: Этап 2 (2.4, 2.15) | D12: окт–ноя | E12: Claude Max + механики/правила CVM
A13: 9. Агент-оператор заведения акций | B13: Вводит акцию в систему: автозаполнение полей, расписание, выгрузка, валидация/QA | C13: Этап 2 (2.3, 2.16) | D13: окт–ноя | E13: Claude Max + интеграции/API заведения

Sheet Стоимость проекта
A1: Стоимость проекта (без НДС). Ставка 4 350 ₽/час
A2: Расчёт является ПРЕДВАРИТЕЛЬНЫМ (оценочным): объём часов — экспертная оценка и может быть уточнён по итогам обследования и согласования объёма работ с заказчиком.
A3: № | B3: Этап / услуга | C3: Ед. | D3: Кол-во часов | E3: Стоимость, ₽
A4: 1. | B4: Этап 1. Персонализация ДЦО (июль-август 2026) | D4: =SUMIFS('Трудоёмкость (детально)'!$L:$L,'Трудоёмкость (детально)'!$B:$B,"Этап 1") | E4: =D4*4350
B5: • Технический блок | C5: чел.-час | D5: =SUMIFS('Трудоёмкость (детально)'!$L:$L,'Трудоёмкость (детально)'!$B:$B,"Этап 1",'Трудоёмкость (детально)'!$D:$D,"Технический") | E5: =D5*4350
B6: • Операционный блок | C6: чел.-час | D6: =SUMIFS('Трудоёмкость (детально)'!$L:$L,'Трудоёмкость (детально)'!$B:$B,"Этап 1",'Трудоёмкость (детально)'!$D:$D,"Операционный") | E6: =D6*4350
A7: 2. | B7: Этап 2. Полноценный CVM: 100 сегментов (сентябрь-ноябрь 2026) | D7: =SUMIFS('Трудоёмкость (детально)'!$L:$L,'Трудоёмкость (детально)'!$B:$B,"Этап 2") | E7: =D7*4350
B8: • Технический блок | C8: чел.-час | D8: =SUMIFS('Трудоёмкость (детально)'!$L:$L,'Трудоёмкость (детально)'!$B:$B,"Этап 2",'Трудоёмкость (детально)'!$D:$D,"Технический") | E8: =D8*4350
B9: • Операционный блок | C9: чел.-час | D9: =SUMIFS('Трудоёмкость (детально)'!$L:$L,'Трудоёмкость (детально)'!$B:$B,"Этап 2",'Трудоёмкость (детально)'!$D:$D,"Операционный") | E9: =D9*4350
A10: 3. | B10: Этап 3. Масштаб + простая оптимизация (декабрь 2026) | D10: =SUMIFS('Трудоёмкость (детально)'!$L:$L,'Трудоёмкость (детально)'!$B:$B,"Этап 3") | E10: =D10*4350
B11: • Технический блок | C11: чел.-час | D11: =SUMIFS('Трудоёмкость (детально)'!$L:$L,'Трудоёмкость (детально)'!$B:$B,"Этап 3",'Трудоёмкость (детально)'!$D:$D,"Технический") | E11: =D11*4350
B12: • Операционный блок | C12: чел.-час | D12: =SUMIFS('Трудоёмкость (детально)'!$L:$L,'Трудоёмкость (детально)'!$B:$B,"Этап 3",'Трудоёмкость (детально)'!$D:$D,"Операционный") | E12: =D12*4350
B13: ИТОГО работы по проекту | D13: =D4+D7+D10 | E13: =E4+E7+E10
B14: в т.ч. в среднем в месяц (6 мес) | E14: =E13/6
B16: Модель: сервис разворачивается на нашем сервере с возможностью последующей передачи заказчику (задача 3.5).
B17: Доп. расходы вне трудозатрат — см. лист «Трудоёмкость (детально)».
